<?xml version="1.0"?>
<sdf version="1.4">
    <model name="wrench_gripper">

        <link name="stand">
            <pose>-.01 0 0 0 0 -1.57079633</pose>
            <inertial>
                <pose>0 0 0.02881 0 0 0</pose>
                <inertia>
                    <ixx>0.5</ixx>
                    <ixy>0</ixy>
                    <ixz>0</ixz>
                    <iyy>0.5</iyy>
                    <iyz>0</iyz>
                    <izz>0.5</izz>
                </inertia>
                <mass>20</mass>
            </inertial>
            <collision name="collision">
                <geometry>
                    <mesh>
                        <uri>file://stand.DAE</uri>
                    </mesh>
                </geometry>
   <surface>
        <friction>
          <ode>
            <mu>0.9</mu>
            <mu2>0.9</mu2>
          </ode>
        </friction>
      </surface>
            </collision>
            <visual name="visual">
                <geometry>
                    <mesh>
                        <uri>file://stand.DAE</uri>
                    </mesh>
                </geometry>
                <material>
                    <script>Gazebo/Purple</script>
                </material>
            </visual>
        </link>


        <link name="base">
            <pose>0 0 0.5 0 0 -1.57079633</pose>
            <inertial>
                <pose>0 0.00501 0.02881 0 0 0</pose>
                <inertia>
                    <ixx>0.000388124</ixx>
                    <ixy>0</ixy>
                    <ixz>0</ixz>
                    <iyy>0.000340362</iyy>
                    <iyz>0</iyz>
                    <izz>0.00003168</izz>
                </inertia>
                <mass>0.14187</mass>
            </inertial>
            <collision name="collision">
                <geometry>
                    <mesh>
                        <uri>file://base.DAE</uri>
                    </mesh>
                </geometry>
            </collision>
            <visual name="visual">
                <geometry>
                    <mesh>
                        <uri>file://base.DAE</uri>
                    </mesh>
                </geometry>
                <material>
                    <script>Gazebo/Purple</script>
                </material>
            </visual>
        </link>
        <link name="link1">
            <pose>0.005 0.0 0.43 0 0 0</pose>
            <inertial>
                <inertia>
                    <ixx>0.01</ixx>
                    <ixy>0</ixy>
                    <ixz>0</ixz>
                    <iyy>0.01</iyy>
                    <iyz>0</iyz>
                    <izz>0.01</izz>
                </inertia>
                <mass>0.5</mass>
            </inertial>
            <collision name="collision">
                <geometry>
                    <mesh>
                        <uri>file://link1.DAE</uri>
                    </mesh>
                </geometry>
            </collision>
            <visual name="visual">
                <geometry>
                    <mesh>
                        <uri>file://link1.DAE</uri>
                    </mesh>
                </geometry>
                <material>
                    <script>Gazebo/Red</script>
                </material>
            </visual>
        </link>
        <link name="link2">
            <pose>0.114 0.0 0.43 0 0 -1.57079633</pose>

            <inertial>
                <inertia>
                    <ixx>0.01</ixx>
                    <ixy>0</ixy>
                    <ixz>0</ixz>
                    <iyy>0.01</iyy>
                    <iyz>0</iyz>
                    <izz>0.01</izz>
                </inertia>
                <mass>0.1</mass>
            </inertial>
            <collision name="collision">
                <geometry>
                    <mesh>
                        <uri>file://link2.DAE</uri>
                    </mesh>
                </geometry>
            </collision>
            <visual name="visual">
                <geometry>
                    <mesh>
                        <uri>file://link2.DAE</uri>
                    </mesh>
                </geometry>
                <material>
                    <script>Gazebo/Blue</script>
                </material>
            </visual>
        </link>
        <link name="tip_left">
            <pose>0.113 0.0125 0.4305 0 0 0</pose>

            <inertial>
                <inertia>
                    <ixx>0.003308444</ixx>
                    <ixy>0</ixy>
                    <ixz>0</ixz>
                    <iyy>0.003308444</iyy>
                    <iyz>0</iyz>
                    <izz>0.003308444</izz>
                </inertia>
                <mass>0.007</mass>
            </inertial>
            <collision name="collision">
                <geometry>
                    <mesh>
                        <uri>file://tip.DAE</uri>
                    </mesh>
                </geometry>
            </collision>
            <visual name="visual">
                <geometry>
                    <mesh>
                        <uri>file://tip.DAE</uri>
                    </mesh>
                </geometry>
                <material>
                    <script>Gazebo/Blue</script>
                </material>
            </visual>
        </link>
        <link name="tip_right">
            <pose>0.113 -0.0125 0.4305 3.14159265359 0 0</pose>

            <inertial>
                <inertia>
                    <ixx>0.003308444</ixx>
                    <ixy>0</ixy>
                    <ixz>0</ixz>
                    <iyy>0.003308444</iyy>
                    <iyz>0</iyz>
                    <izz>0.003308444</izz>
                </inertia>
                <mass>0.007</mass>
            </inertial>
            <collision name="collision">
                <geometry>
                    <mesh>
                        <uri>file://tip.DAE</uri>
                    </mesh>
                </geometry>
            </collision>
            <visual name="visual">
                <geometry>
                    <mesh>
                        <uri>file://tip.DAE</uri>
                    </mesh>
                </geometry>
                <material>
                    <script>Gazebo/Blue</script>
                </material>
            </visual>
        </link>

        <static>false</static>
<joint name="left_tip_joint" type="revolute">
            <pose>0 0 0 0 0 0</pose>
            <child>tip_left</child>
            <parent>link2</parent>
            <axis>
                <limit>
                    <lower>0</lower>
                    <upper>0.645772</upper>
                </limit>
                <xyz>0 0 1</xyz>
            </axis>
        </joint>
        <joint name="right_tip_joint" type="revolute">
            <pose>0 0 0 0 0 0</pose>
            <child>tip_right</child>
            <parent>link2</parent>
            <axis>
                <limit>
                    <lower>-0.645772</lower>
                    <upper>0</upper>
                </limit>
                <xyz>0 0 1</xyz>
            </axis>
        </joint>

<joint name="base_joint" type="revolute">
            <pose>0 0 0 0 0 0</pose>
  <child>link1</child>  
 <parent>base</parent>
            <axis>
                <limit>
                    <lower>0</lower>
                    <upper>0</upper>
                </limit>
                <xyz>0 0 0</xyz>
            </axis>
</joint>

<joint name="link1_joint" type="revolute">
            <pose>0 0 0 0 0 0</pose>
  <child>link2</child>  
 <parent>link1</parent>
            <axis>
                <limit>
                    <lower>0</lower>
                    <upper>0</upper>
                </limit>
                <xyz>0 0 0</xyz>
            </axis>
</joint>

<joint name="stand_joint" type="revolute">
            <pose>0 0 0 0 0 0</pose>
  <child>base</child>  
 <parent>stand</parent>
            <axis>
                <limit>
                    <lower>0</lower>
                    <upper>0</upper>
                </limit>
                <xyz>0 0 0</xyz>
            </axis>
</joint>

 <transmission name="tran1">
    <type>transmission_interface/SimpleTransmission</type>
    <joint name="left_tip_joint">
      <hardwareInterface>EffortJointInterface</hardwareInterface>
    </joint>
    <actuator name="motor1">
      <hardwareInterface>EffortJointInterface</hardwareInterface>
      <mechanicalReduction>1</mechanicalReduction>
    </actuator>
  </transmission>

  <transmission name="tran2">
    <type>transmission_interface/SimpleTransmission</type>
    <joint name="right_tip_joint">
      <hardwareInterface>EffortJointInterface</hardwareInterface>
    </joint>
    <actuator name="motor2">
      <hardwareInterface>EffortJointInterface</hardwareInterface>
      <mechanicalReduction>1</mechanicalReduction>
    </actuator>
  </transmission>


    </model>
</sdf>
